Workbook

Sheet Employee Database
A1: 🏢 EMPLOYEE MASTER DATABASE – 2024 | B1: Column1 | C1: Column2 | D1: Column210 | E1: Column3 | F1: Column4 | G1: Column5 | H1: Column6 | I1: Column7 | J1: Column8 | K1: Column9 | L1: Column10 | M1: Column11 | N1: Column12 | O1: Column13 | P1: Column14 | Q1: Column15 | R1: Column16 | S1: Column17 | T1: Column18 | U1: Column19 | V1: Column20 | W1: Column21 | X1: Column22 | Y1: Column23 | Z1: Column24 | AA1: Column25 | AB1: Column26 | AC1: Column27 | AD1: Column28 | AE1: Column29 | AF1: Column30 | AG1: Column31 | AH1: Column32 | AI1: Column33 | AJ1: Column34 | AK1: Column35 | AL1: Column36 | AM1: Column37 | AN1: Column38 | AO1: Column39 | AP1: Column40 | AQ1: Column41 | AR1: Column42 | AS1: Column43
A2: Emp ID | B2: Full Name | C2: First Nam,e | D2: Last Nam,e | E2: Department | G2: Designation | H2: Gender | I2: Age | J2: Date of Join | K2: Experience(Yrs) | L2: City | M2: Basic Salary | N2: HRA | O2: Allowances | P2: Gross Salary | Q2: Tax (10%) | R2: Net Salary | S2: Performance | T2: Rating (1-5) | U2: Bonus | V2: Email | W2: Phone | X2: Join Month | Y2: Salary Band | Z2: Text Function | AA2: Email
A3: EMP101 | B3: Aarav Sharma | C3: Aarav | D3: aharma | E3: IT | F3: =LOWER(G3) -> software engineer | G3: software Engineer | H3: Male | I3: 28 | J3: 2019-03-15 | K3: =DATEDIF(J3,TODAY(),"Y") -> 7 | L3: Mumbai | M3: 65000 | N3: 26000 | O3: =M3*0.2 -> 13000 | P3: =M3+N3+O3 -> 104000 | Q3: =P3*0.1 -> 10400 | R3: =P3-Q3 -> 93600 | S3: Excellent | T3: 4 | U3: =IF(T3>=4,P3*0.05,P3*0.02) -> 5200 | V3: =LOWER(LEFT(B3,FIND(" ",B3)-1))&"."&LOWER(MID(B3,FIND(" ",B3)+1,100))&"@company.com" -> aarav.sharma@company.com | W3: +91-9800000007 | X3: =TEXT(J3,"MMM-YYYY") -> Mar-2019 | Y3: =IF(M3>=100000,"Executive",IF(M3>=80000,"Senior",IF(M3>=60000,"Mid-Level","Junior"))) -> Mid-Level | Z3: =UPPER(B3) -> AARAV SHARMA | AA3: =LOWER(V3) -> aarav.sharma@company.com | AB3: =PROPER(G3) -> Software Engineer | AC3: =BAHTTEXT(T3) -> สี่บาทถ้วน | AD3: =LEFT(B3,1) -> A | AE3: =CODE(AD3) -> 65 | AF3: =CHAR(AE3) -> A | AG3: Hello Red & White Skill Education | AH3: =CLEAN(AG3) -> Hello Red & White Skill Education | AI3: =DOLLAR(AE3) -> ₹ 65.00 | AJ3: =EXACT(AB3,G3) -> FALSE | AK3: =_xlfn.CONCAT(B3," :",G3) -> Aarav Sharma : software Engineer | AL3: =LEN(S3) -> 9 | AM3: =_xlfn.CONCAT(K3,"EXP") -> 7EXP | AN3: =_xlfn.NUMBERVALUE(LEFT(AM3,1)) -> 7 | AO3: =REPLACE(AM3,2,3,"Exprience") -> 7Exprience | AP3: =REPT(AM3,5) -> 7EXP7EXP7EXP7EXP7EXP | AQ3: =RIGHT(AM3,3) -> EXP | AR3: =SUBSTITUTE(AM3,"Experience",1) -> 7EXP | AS3: =T(AO3) -> 7Exprience
A4: EMP102 | B4: Priya Patel | C4: Priya | D4: patel | E4: HR | F4: =LOWER(G4) -> hr manager | G4: HR Manager | H4: Female | I4: 35 | J4: 2017-06-01 | K4: =DATEDIF(J4,TODAY(),"Y") -> 8 | L4: Ahmedabad | M4: 72000 | N4: 28800 | O4: =M4*0.2 -> 14400 | P4: =M4+N4+O4 -> 115200 | Q4: =P4*0.1 -> 11520 | R4: =P4-Q4 -> 103680 | S4: Good | T4: 3 | U4: =IF(T4>=4,P4*0.05,P4*0.02) -> 2304 | V4: =LOWER(LEFT(B4,FIND(" ",B4)-1))&"."&LOWER(MID(B4,FIND(" ",B4)+1,100))&"@company.com" -> priya.patel@company.com | W4: +91-9800000020 | X4: =TEXT(J4,"MMM-YYYY") -> Jun-2017 | Y4: =IF(M4>=100000,"Executive",IF(M4>=80000,"Senior",IF(M4>=60000,"Mid-Level","Junior"))) -> Mid-Level | Z4: =UPPER(B4) -> PRIYA PATEL | AA4: =LOWER(V4) -> priya.patel@company.com | AB4: =PROPER(G4) -> Hr Manager | AC4: =BAHTTEXT(T4) -> สามบาทถ้วน | AD4: =LEFT(B4,1) -> P | AE4: =CODE(AD4) -> 80 | AF4: =CHAR(AE4) -> P | AI4: =DOLLAR(AE4) -> ₹ 80.00 | AJ4: =EXACT(AB4,G4) -> FALSE | AK4: =_xlfn.CONCAT(B4," :",G4) -> Priya Patel :HR Manager | AL4: =LEN(S4) -> 4 | AM4: =_xlfn.CONCAT(K4,"EXP") -> 8EXP | AN4: =_xlfn.NUMBERVALUE(LEFT(AM4,1)) -> 8 | AO4: =REPLACE(AM4,2,3,"Exprience") -> 8Exprience | AQ4: =RIGHT(AM4,3) -> EXP | AS4: =T(AL4)
A5: EMP103 | B5: Rohit Mehta | C5: Rohit | D5: rehta | E5: Finance | F5: =LOWER(G5) -> financial analyst | G5: Financial Analyst | H5: Male | I5: 32 | J5: 2018-09-10 | K5: =DATEDIF(J5,TODAY(),"Y") -> 7 | L5: Delhi | M5: 68000 | N5: 27200 | O5: =M5*0.2 -> 13600 | P5: =M5+N5+O5 -> 108800 | Q5: =P5*0.1 -> 10880 | R5: =P5-Q5 -> 97920 | S5: Excellent | T5: 5 | U5: =IF(T5>=4,P5*0.05,P5*0.02) -> 5440 | V5: =LOWER(LEFT(B5,FIND(" ",B5)-1))&"."&LOWER(MID(B5,FIND(" ",B5)+1,100))&"@company.com" -> rohit.mehta@company.com | W5: +91-9800000033 | X5: =TEXT(J5,"MMM-YYYY") -> Sep-2018 | Y5: =IF(M5>=100000,"Executive",IF(M5>=80000,"Senior",IF(M5>=60000,"Mid-Level","Junior"))) -> Mid-Level | Z5: =UPPER(B5) -> ROHIT MEHTA | AA5: =LOWER(V5) -> rohit.mehta@company.com | AB5: =PROPER(G5) -> Financial Analyst | AC5: =BAHTTEXT(T5) -> ห้าบาทถ้วน | AD5: =LEFT(B5,1) -> R | AE5: =CODE(AD5) -> 82 | AF5: =CHAR(AE5) -> R | AI5: =DOLLAR(AE5) -> ₹ 82.00 | AJ5: =EXACT(AB5,G5) -> TRUE | AK5: =_xlfn.CONCAT(B5," :",G5) -> Rohit Mehta :Financial Analyst | AL5: =LEN(S5) -> 9 | AM5: =_xlfn.CONCAT(K5,"EXP") -> 7EXP | AN5: =_xlfn.NUMBERVALUE(LEFT(AM5,1)) -> 7 | AO5: =REPLACE(AM5,2,3,"Exprience") -> 7Exprience | AQ5: =RIGHT(AM5,3) -> EXP
A6: EMP104 | B6: Sneha Reddy | C6: Sneha | D6: seddy | E6: IT | F6: =LOWER(G6) -> full stack developer | G6: Full Stack Developer | H6: Female | I6: 26 | J6: 2021-01-20 | K6: =DATEDIF(J6,TODAY(),"Y") -> 5 | L6: Hyderabad | M6: 70000 | N6: 28000 | O6: =M6*0.2 -> 14000 | P6: =M6+N6+O6 -> 112000 | Q6: =P6*0.1 -> 11200 | R6: =P6-Q6 -> 100800 | S6: Good | T6: 4 | U6: =IF(T6>=4,P6*0.05,P6*0.02) -> 5600 | V6: =LOWER(LEFT(B6,FIND(" ",B6)-1))&"."&LOWER(MID(B6,FIND(" ",B6)+1,100))&"@company.com" -> sneha.reddy@company.com | W6: +91-9800000046 | X6: =TEXT(J6,"MMM-YYYY") -> Jan-2021 | Y6: =IF(M6>=100000,"Executive",IF(M6>=80000,"Senior",IF(M6>=60000,"Mid-Level","Junior"))) -> Mid-Level | Z6: =UPPER(B6) -> SNEHA REDDY | AA6: =LOWER(V6) -> sneha.reddy@company.com | AB6: =PROPER(G6) -> Full Stack Developer | AC6: =BAHTTEXT(T6) -> สี่บาทถ้วน | AD6: =LEFT(B6,1) -> S | AE6: =CODE(AD6) -> 83 | AF6: =CHAR(AE6) -> S | AI6: =DOLLAR(AE6) -> ₹ 83.00 | AJ6: =EXACT(AB6,G6) -> TRUE | AK6: =_xlfn.CONCAT(B6," :",G6) -> Sneha Reddy :Full Stack Developer | AL6: =LEN(S6) -> 4 | AM6: =_xlfn.CONCAT(K6,"EXP") -> 5EXP | AN6: =_xlfn.NUMBERVALUE(LEFT(AM6,1)) -> 5 | AO6: =REPLACE(AM6,2,3,"Exprience") -> 5Exprience | AQ6: =RIGHT(AM6,3) -> EXP | AR6: =VALUE(AL6) -> 4 | AS6: =TEXT(AL6,"Hello") -> 01900llo
A7: EMP105 | B7: Vikram Singh | C7: Vikram | D7: vingh | E7: Sales | F7: =LOWER(G7) -> sales executive | G7: Sales Executive | H7: Male | I7: 30 | J7: 2020-07-05 | K7: =DATEDIF(J7,TODAY(),"Y") -> 5 | L7: Jaipur | M7: 45000 | N7: 18000 | O7: =M7*0.2 -> 9000 | P7: =M7+N7+O7 -> 72000 | Q7: =P7*0.1 -> 7200 | R7: =P7-Q7 -> 64800 | S7: Average | T7: 3 | U7: =IF(T7>=4,P7*0.05,P7*0.02) -> 1440 | V7: =LOWER(LEFT(B7,FIND(" ",B7)-1))&"."&LOWER(MID(B7,FIND(" ",B7)+1,100))&"@company.com" -> vikram.singh@company.com | W7: +91-9800000059 | X7: =TEXT(J7,"MMM-YYYY") -> Jul-2020 | Y7: =IF(M7>=100000,"Executive",IF(M7>=80000,"Senior",IF(M7>=60000,"Mid-Level","Junior"))) -> Junior | Z7: =UPPER(B7) -> VIKRAM SINGH | AA7: =LOWER(V7) -> vikram.singh@company.com | AB7: =PROPER(G7) -> Sales Executive | AC7: =BAHTTEXT(T7) -> สามบาทถ้วน | AD7: =LEFT(B7,1) -> V | AE7: =CODE(AD7) -> 86 | AF7: =CHAR(AE7) -> V | AI7: =DOLLAR(AE7) -> ₹ 86.00 | AJ7: =EXACT(AB7,G7) -> TRUE | AK7: =_xlfn.CONCAT(B7," :",G7) -> Vikram Singh :Sales Executive | AL7: =LEN(S7) -> 7 | AM7: =_xlfn.CONCAT(K7,"EXP") -> 5EXP | AN7: =_xlfn.NUMBERVALUE(LEFT(AM7,1)) -> 5 | AO7: =REPLACE(AM7,2,3,"Exprience") -> 5Exprience | AQ7: =RIGHT(AM7,3) -> EXP
A8: EMP106 | B8: Kavya Nair | C8: Kavya | D8: kair | E8: Marketing | F8: =LOWER(G8) -> marketing manager | G8: Marketing Manager | H8: Female | I8: 38 | J8: 2015-11-12 | K8: =DATEDIF(J8,TODAY(),"Y") -> 10 | L8: Kochi | M8: 80000 | N8: 32000 | O8: =M8*0.2 -> 16000 | P8: =M8+N8+O8 -> 128000 | Q8: =P8*0.1 -> 12800 | R8: =P8-Q8 -> 115200 | S8: Excellent | T8: 5 | U8: =IF(T8>=4,P8*0.05,P8*0.02) -> 6400 | V8: =LOWER(LEFT(B8,FIND(" ",B8)-1))&"."&LOWER(MID(B8,FIND(" ",B8)+1,100))&"@company.com" -> kavya.nair@company.com | W8: +91-9800000072 | X8: =TEXT(J8,"MMM-YYYY") -> Nov-2015 | Y8: =IF(M8>=100000,"Executive",IF(M8>=80000,"Senior",IF(M8>=60000,"Mid-Level","Junior"))) -> Senior | Z8: =UPPER(B8) -> KAVYA NAIR | AA8: =LOWER(V8) -> kavya.nair@company.com | AB8: =PROPER(G8) -> Marketing Manager | AC8: =BAHTTEXT(T8) -> ห้าบาทถ้วน | AD8: =LEFT(B8,1) -> K | AE8: =CODE(AD8) -> 75 | AF8: =CHAR(AE8) -> K | AI8: =DOLLAR(AE8) -> ₹ 75.00 | AJ8: =EXACT(AB8,G8) -> TRUE | AK8: =_xlfn.CONCAT(B8," :",G8) -> Kavya Nair :Marketing Manager | AL8: =LEN(S8) -> 9 | AM8: =_xlfn.CONCAT(K8,"EXP") -> 10EXP | AN8: =_xlfn.NUMBERVALUE(LEFT(AM8,1)) -> 1 | AO8: =REPLACE(AM8,2,3,"Exprience") -> 1ExprienceP | AQ8: =RIGHT(AM8,3) -> EXP | AR8: =VALUE(AL8) -> 9
A9: EMP107 | B9: Arjun Kumar | C9: Arjun | D9: aumar | E9: IT | F9: =LOWER(G9) -> data scientist | G9: Data Scientist | H9: Male | I9: 29 | J9: 2020-04-18 | K9: =DATEDIF(J9,TODAY(),"Y") -> 6 | L9: Bangalore | M9: 90000 | N9: 36000 | O9: =M9*0.2 -> 18000 | P9: =M9+N9+O9 -> 144000 | Q9: =P9*0.1 -> 14400 | R9: =P9-Q9 -> 129600 | S9: Outstanding | T9: 5 | U9: =IF(T9>=4,P9*0.05,P9*0.02) -> 7200 | V9: =LOWER(LEFT(B9,FIND(" ",B9)-1))&"."&LOWER(MID(B9,FIND(" ",B9)+1,100))&"@company.com" -> arjun.kumar@company.com | W9: +91-9800000085 | X9: =TEXT(J9,"MMM-YYYY") -> Apr-2020 | Y9: =IF(M9>=100000,"Executive",IF(M9>=80000,"Senior",IF(M9>=60000,"Mid-Level","Junior"))) -> Senior | Z9: =UPPER(B9) -> ARJUN KUMAR | AA9: =LOWER(V9) -> arjun.kumar@company.com | AB9: =PROPER(G9) -> Data Scientist | AC9: =BAHTTEXT(T9) -> ห้าบาทถ้วน | AD9: =LEFT(B9,1) -> A | AE9: =CODE(AD9) -> 65 | AF9: =CHAR(AE9) -> A | AI9: =DOLLAR(AE9) -> ₹ 65.00 | AJ9: =EXACT(AB9,G9) -> TRUE | AK9: =_xlfn.CONCAT(B9," :",G9) -> Arjun Kumar :Data Scientist | AL9: =LEN(S9) -> 11 | AM9: =_xlfn.CONCAT(K9,"EXP") -> 6EXP | AN9: =_xlfn.NUMBERVALUE(LEFT(AM9,1)) -> 6 | AO9: =REPLACE(AM9,2,3,"Exprience") -> 6Exprience | AQ9: =RIGHT(AM9,3) -> EXP
A10: EMP108 | B10: Divya Verma | C10: Divya | D10: derma | E10: Finance | F10: =LOWER(G10) -> accountant | G10: Accountant | H10: Female | I10: 27 | J10: 2022-02-28 | K10: =DATEDIF(J10,TODAY(),"Y") -> 4 | L10: Pune | M10: 55000 | N10: 22000 | O10: =M10*0.2 -> 11000 | P10: =M10+N10+O10 -> 88000 | Q10: =P10*0.1 -> 8800 | R10: =P10-Q10 -> 79200 | S10: Good | T10: 3 | U10: =IF(T10>=4,P10*0.05,P10*0.02) -> 1760 | V10: =LOWER(LEFT(B10,FIND(" ",B10)-1))&"."&LOWER(MID(B10,FIND(" ",B10)+1,100))&"@company.com" -> divya.verma@company.com | W10: +91-9800000098 | X10: =TEXT(J10,"MMM-YYYY") -> Feb-2022 | Y10: =IF(M10>=100000,"Executive",IF(M10>=80000,"Senior",IF(M10>=60000,"Mid-Level","Junior"))) -> Junior | Z10: =UPPER(B10) -> DIVYA VERMA | AA10: =LOWER(V10) -> divya.verma@company.com | AB10: =PROPER(G10) -> Accountant | AC10: =BAHTTEXT(T10) -> สามบาทถ้วน | AD10: =LEFT(B10,1) -> D | AE10: =CODE(AD10) -> 68 | AF10: =CHAR(AE10) -> D | AI10: =DOLLAR(AE10) -> ₹ 68.00 | AJ10: =EXACT(AB10,G10) -> TRUE | AK10: =_xlfn.CONCAT(B10," :",G10) -> Divya Verma :Accountant | AL10: =LEN(S10) -> 4 | AM10: =_xlfn.CONCAT(K10,"EXP") -> 4EXP | AN10: =_xlfn.NUMBERVALUE(LEFT(AM10,1)) -> 4 | AO10: =REPLACE(AM10,2,3,"Exprience") -> 4Exprience | AQ10: =RIGHT(AM10,3) -> EXP
A11: EMP109 | B11: Ravi Tiwari | C11: Ravi | D11: riwari | E11: Sales | F11: =LOWER(G11) -> regional manager | G11: Regional Manager | H11: Male | I11: 42 | J11: 2013-08-30 | K11: =DATEDIF(J11,TODAY(),"Y") -> 12 | L11: Lucknow | M11: 95000 | N11: 38000 | O11: =M11*0.2 -> 19000 | P11: =M11+N11+O11 -> 152000 | Q11: =P11*0.1 -> 15200 | R11: =P11-Q11 -> 136800 | S11: Outstanding | T11: 5 | U11: =IF(T11>=4,P11*0.05,P11*0.02) -> 7600 | V11: =LOWER(LEFT(B11,FIND(" ",B11)-1))&"."&LOWER(MID(B11,FIND(" ",B11)+1,100))&"@company.com" -> ravi.tiwari@company.com | W11: +91-9800000111 | X11: =TEXT(J11,"MMM-YYYY") -> Aug-2013 | Y11: =IF(M11>=100000,"Executive",IF(M11>=80000,"Senior",IF(M11>=60000,"Mid-Level","Junior"))) -> Senior | Z11: =UPPER(B11) -> RAVI TIWARI | AA11: =LOWER(V11) -> ravi.tiwari@company.com | AB11: =PROPER(G11) -> Regional Manager | AC11: =BAHTTEXT(T11) -> ห้าบาทถ้วน | AD11: =LEFT(B11,1) -> R | AE11: =CODE(AD11) -> 82 | AF11: =CHAR(AE11) -> R | AI11: =DOLLAR(AE11) -> ₹ 82.00 | AJ11: =EXACT(AB11,G11) -> TRUE | AK11: =_xlfn.CONCAT(B11," :",G11) -> Ravi Tiwari :Regional Manager | AL11: =LEN(S11) -> 11 | AM11: =_xlfn.CONCAT(K11,"EXP") -> 12EXP | AN11: =_xlfn.NUMBERVALUE(LEFT(AM11,1)) -> 1 | AO11: =REPLACE(AM11,2,3,"Exprience") -> 1ExprienceP | AQ11: =RIGHT(AM11,3) -> EXP
A12: EMP110 | B12: Anjali Mishra | C12: Anjali | D12: aishra | E12: HR | F12: =LOWER(G12) -> recruiter | G12: Recruiter | H12: Female | I12: 25 | J12: 2023-03-01 | K12: =DATEDIF(J12,TODAY(),"Y") -> 3 | L12: Bhopal | M12: 40000 | N12: 16000 | O12: =M12*0.2 -> 8000 | P12: =M12+N12+O12 -> 64000 | Q12: =P12*0.1 -> 6400 | R12: =P12-Q12 -> 57600 | S12: Average | T12: 2 | U12: =IF(T12>=4,P12*0.05,P12*0.02) -> 1280 | V12: =LOWER(LEFT(B12,FIND(" ",B12)-1))&"."&LOWER(MID(B12,FIND(" ",B12)+1,100))&"@company.com" -> anjali.mishra@company.com | W12: +91-9800000124 | X12: =TEXT(J12,"MMM-YYYY") -> Mar-2023 | Y12: =IF(M12>=100000,"Executive",IF(M12>=80000,"Senior",IF(M12>=60000,"Mid-Level","Junior"))) -> Junior | Z12: =UPPER(B12) -> ANJALI MISHRA | AA12: =LOWER(V12) -> anjali.mishra@company.com | AB12: =PROPER(G12) -> Recruiter | AC12: =BAHTTEXT(T12) -> สองบาทถ้วน | AD12: =LEFT(B12,1) -> A | AE12: =CODE(AD12) -> 65 | AF12: =CHAR(AE12) -> A | AI12: =DOLLAR(AE12) -> ₹ 65.00 | AJ12: =EXACT(AB12,G12) -> TRUE | AK12: =_xlfn.CONCAT(B12," :",G12) -> Anjali Mishra :Recruiter | AL12: =LEN(S12) -> 7 | AM12: =_xlfn.CONCAT(K12,"EXP") -> 3EXP | AN12: =_xlfn.NUMBERVALUE(LEFT(AM12,1)) -> 3 | AO12: =REPLACE(AM12,2,3,"Exprience") -> 3Exprience | AQ12: =RIGHT(AM12,3) -> EXP
A13: EMP111 | B13: Suresh Gupta | C13: Suresh | D13: supta | E13: IT | F13: =LOWER(G13) -> devops engineer | G13: DevOps Engineer | H13: Male | I13: 33 | J13: 2019-05-22 | K13: =DATEDIF(J13,TODAY(),"Y") -> 6 | L13: Chennai | M13: 78000 | N13: 31200 | O13: =M13*0.2 -> 15600 | P13: =M13+N13+O13 -> 124800 | Q13: =P13*0.1 -> 12480 | R13: =P13-Q13 -> 112320 | S13: Good | T13: 4 | U13: =IF(T13>=4,P13*0.05,P13*0.02) -> 6240 | V13: =LOWER(LEFT(B13,FIND(" ",B13)-1))&"."&LOWER(MID(B13,FIND(" ",B13)+1,100))&"@company.com" -> suresh.gupta@company.com | W13: +91-9800000137 | X13: =TEXT(J13,"MMM-YYYY") -> May-2019 | Y13: =IF(M13>=100000,"Executive",IF(M13>=80000,"Senior",IF(M13>=60000,"Mid-Level","Junior"))) -> Mid-Level | Z13: =UPPER(B13) -> SURESH GUPTA | AA13: =LOWER(V13) -> suresh.gupta@company.com | AB13: =PROPER(G13) -> Devops Engineer | AC13: =BAHTTEXT(T13) -> สี่บาทถ้วน | AD13: =LEFT(B13,1) -> S | AE13: =CODE(AD13) -> 83 | AF13: =CHAR(AE13) -> S | AI13: =DOLLAR(AE13) -> ₹ 83.00 | AJ13: =EXACT(AB13,G13) -> FALSE | AK13: =_xlfn.CONCAT(B13," :",G13) -> Suresh Gupta :DevOps Engineer | AL13: =LEN(S13) -> 4 | AM13: =_xlfn.CONCAT(K13,"EXP") -> 6EXP | AN13: =_xlfn.NUMBERVALUE(LEFT(AM13,1)) -> 6 | AO13: =REPLACE(AM13,2,3,"Exprience") -> 6Exprience | AQ13: =RIGHT(AM13,3) -> EXP
A14: EMP112 | B14: Meera Joshi | C14: Meera | D14: moshi | E14: Marketing | F14: =LOWER(G14) -> content strategist | G14: Content Strategist | H14: Female | I14: 29 | J14: 2021-09-14 | K14: =DATEDIF(J14,TODAY(),"Y") -> 4 | L14: Indore | M14: 52000 | N14: 20800 | O14: =M14*0.2 -> 10400 | P14: =M14+N14+O14 -> 83200 | Q14: =P14*0.1 -> 8320 | R14: =P14-Q14 -> 74880 | S14: Good | T14: 3 | U14: =IF(T14>=4,P14*0.05,P14*0.02) -> 1664 | V14: =LOWER(LEFT(B14,FIND(" ",B14)-1))&"."&LOWER(MID(B14,FIND(" ",B14)+1,100))&"@company.com" -> meera.joshi@company.com | W14: +91-9800000150 | X14: =TEXT(J14,"MMM-YYYY") -> Sep-2021 | Y14: =IF(M14>=100000,"Executive",IF(M14>=80000,"Senior",IF(M14>=60000,"Mid-Level","Junior"))) -> Junior | Z14: =UPPER(B14) -> MEERA JOSHI | AA14: =LOWER(V14) -> meera.joshi@company.com | AB14: =PROPER(G14) -> Content Strategist | AC14: =BAHTTEXT(T14) -> สามบาทถ้วน | AD14: =LEFT(B14,1) -> M | AE14: =CODE(AD14) -> 77 | AF14: =CHAR(AE14) -> M | AI14: =DOLLAR(AE14) -> ₹ 77.00 | AJ14: =EXACT(AB14,G14) -> TRUE | AK14: =_xlfn.CONCAT(B14," :",G14) -> Meera Joshi :Content Strategist | AL14: =LEN(S14) -> 4 | AM14: =_xlfn.CONCAT(K14,"EXP") -> 4EXP | AN14: =_xlfn.NUMBERVALUE(LEFT(AM14,1)) -> 4 | AO14: =REPLACE(AM14,2,3,"Exprience") -> 4Exprience | AQ14: =RIGHT(AM14,3) -> EXP
A15: EMP113 | B15: Nikhil Pandey | C15: Nikhil | D15: nandey | E15: Finance | F15: =LOWER(G15) -> senior accountant | G15: Senior Accountant | H15: Male | I15: 36 | J15: 2016-12-03 | K15: =DATEDIF(J15,TODAY(),"Y") -> 9 | L15: Varanasi | M15: 74000 | N15: 29600 | O15: =M15*0.2 -> 14800 | P15: =M15+N15+O15 -> 118400 | Q15: =P15*0.1 -> 11840 | R15: =P15-Q15 -> 106560 | S15: Excellent | T15: 4 | U15: =IF(T15>=4,P15*0.05,P15*0.02) -> 5920 | V15: =LOWER(LEFT(B15,FIND(" ",B15)-1))&"."&LOWER(MID(B15,FIND(" ",B15)+1,100))&"@company.com" -> nikhil.pandey@company.com | W15: +91-9800000163 | X15: =TEXT(J15,"MMM-YYYY") -> Dec-2016 | Y15: =IF(M15>=100000,"Executive",IF(M15>=80000,"Senior",IF(M15>=60000,"Mid-Level","Junior"))) -> Mid-Level | Z15: =UPPER(B15) -> NIKHIL PANDEY | AA15: =LOWER(V15) -> nikhil.pandey@company.com | AB15: =PROPER(G15) -> Senior Accountant | AC15: =BAHTTEXT(T15) -> สี่บาทถ้วน | AD15: =LEFT(B15,1) -> N | AE15: =CODE(AD15) -> 78 | AF15: =CHAR(AE15) -> N | AI15: =DOLLAR(AE15) -> ₹ 78.00 | AJ15: =EXACT(AB15,G15) -> TRUE | AK15: =_xlfn.CONCAT(B15," :",G15) -> Nikhil Pandey :Senior Accountant | AL15: =LEN(S15) -> 9 | AM15: =_xlfn.CONCAT(K15,"EXP") -> 9EXP | AN15: =_xlfn.NUMBERVALUE(LEFT(AM15,1)) -> 9 | AO15: =REPLACE(AM15,2,3,"Exprience") -> 9Exprience | AQ15: =RIGHT(AM15,3) -> EXP
A16: EMP114 | B16: Pooja Yadav | C16: Pooja | D16: padav | E16: IT | F16: =LOWER(G16) -> qa engineer | G16: QA Engineer | H16: Female | I16: 27 | J16: 2022-06-17 | K16: =DATEDIF(J16,TODAY(),"Y") -> 3 | L16: Nagpur | M16: 58000 | N16: 23200 | O16: =M16*0.2 -> 11600 | P16: =M16+N16+O16 -> 92800 | Q16: =P16*0.1 -> 9280 | R16: =P16-Q16 -> 83520 | S16: Average | T16: 3 | U16: =IF(T16>=4,P16*0.05,P16*0.02) -> 1856 | V16: =LOWER(LEFT(B16,FIND(" ",B16)-1))&"."&LOWER(MID(B16,FIND(" ",B16)+1,100))&"@company.com" -> pooja.yadav@company.com | W16: +91-9800000176 | X16: =TEXT(J16,"MMM-YYYY") -> Jun-2022 | Y16: =IF(M16>=100000,"Executive",IF(M16>=80000,"Senior",IF(M16>=60000,"Mid-Level","Junior"))) -> Junior | Z16: =UPPER(B16) -> POOJA YADAV | AA16: =LOWER(V16) -> pooja.yadav@company.com | AB16: =PROPER(G16) -> Qa Engineer | AC16: =BAHTTEXT(T16) -> สามบาทถ้วน | AD16: =LEFT(B16,1) -> P | AE16: =CODE(AD16) -> 80 | AF16: =CHAR(AE16) -> P | AI16: =DOLLAR(AE16) -> ₹ 80.00 | AJ16: =EXACT(AB16,G16) -> FALSE | AK16: =_xlfn.CONCAT(B16," :",G16) -> Pooja Yadav :QA Engineer | AL16: =LEN(S16) -> 7 | AM16: =_xlfn.CONCAT(K16,"EXP") -> 3EXP | AN16: =_xlfn.NUMBERVALUE(LEFT(AM16,1)) -> 3 | AO16: =REPLACE(AM16,2,3,"Exprience") -> 3Exprience | AQ16: =RIGHT(AM16,3) -> EXP
A17: EMP115 | B17: Manoj Desai | C17: Manoj | D17: mesai | E17: Sales | F17: =LOWER(G17) -> sales manager | G17: Sales Manager | H17: Male | I17: 40 | J17: 2014-10-25 | K17: =DATEDIF(J17,TODAY(),"Y") -> 11 | L17: Surat | M17: 88000 | N17: 35200 | O17: =M17*0.2 -> 17600 | P17: =M17+N17+O17 -> 140800 | Q17: =P17*0.1 -> 14080 | R17: =P17-Q17 -> 126720 | S17: Outstanding | T17: 5 | U17: =IF(T17>=4,P17*0.05,P17*0.02) -> 7040 | V17: =LOWER(LEFT(B17,FIND(" ",B17)-1))&"."&LOWER(MID(B17,FIND(" ",B17)+1,100))&"@company.com" -> manoj.desai@company.com | W17: +91-9800000189 | X17: =TEXT(J17,"MMM-YYYY") -> Oct-2014 | Y17: =IF(M17>=100000,"Executive",IF(M17>=80000,"Senior",IF(M17>=60000,"Mid-Level","Junior"))) -> Senior | Z17: =UPPER(B17) -> MANOJ DESAI | AA17: =LOWER(V17) -> manoj.desai@company.com | AB17: =PROPER(G17) -> Sales Manager | AC17: =BAHTTEXT(T17) -> ห้าบาทถ้วน | AD17: =LEFT(B17,1) -> M | AE17: =CODE(AD17) -> 77 | AF17: =CHAR(AE17) -> M | AI17: =DOLLAR(AE17) -> ₹ 77.00 | AJ17: =EXACT(AB17,G17) -> TRUE | AK17: =_xlfn.CONCAT(B17," :",G17) -> Manoj Desai :Sales Manager | AL17: =LEN(S17) -> 11 | AM17: =_xlfn.CONCAT(K17,"EXP") -> 11EXP | AN17: =_xlfn.NUMBERVALUE(LEFT(AM17,1)) -> 1 | AO17: =REPLACE(AM17,2,3,"Exprience") -> 1ExprienceP | AQ17: =RIGHT(AM17,3) -> EXP
A18: EMP116 | B18: Lakshmi Iyer | C18: Lakshmi | D18: lyer | E18: HR | F18: =LOWER(G18) -> training specialist | G18: Training Specialist | H18: Female | I18: 31 | J18: 2019-07-08 | K18: =DATEDIF(J18,TODAY(),"Y") -> 6 | L18: Madurai | M18: 62000 | N18: 24800 | O18: =M18*0.2 -> 12400 | P18: =M18+N18+O18 -> 99200 | Q18: =P18*0.1 -> 9920 | R18: =P18-Q18 -> 89280 | S18: Good | T18: 4 | U18: =IF(T18>=4,P18*0.05,P18*0.02) -> 4960 | V18: =LOWER(LEFT(B18,FIND(" ",B18)-1))&"."&LOWER(MID(B18,FIND(" ",B18)+1,100))&"@company.com" -> lakshmi.iyer@company.com | W18: +91-9800000202 | X18: =TEXT(J18,"MMM-YYYY") -> Jul-2019 | Y18: =IF(M18>=100000,"Executive",IF(M18>=80000,"Senior",IF(M18>=60000,"Mid-Level","Junior"))) -> Mid-Level | Z18: =UPPER(B18) -> LAKSHMI IYER | AA18: =LOWER(V18) -> lakshmi.iyer@company.com | AB18: =PROPER(G18) -> Training Specialist | AC18: =BAHTTEXT(T18) -> สี่บาทถ้วน | AD18: =LEFT(B18,1) -> L | AE18: =CODE(AD18) -> 76 | AF18: =CHAR(AE18) -> L | AI18: =DOLLAR(AE18) -> ₹ 76.00 | AJ18: =EXACT(AB18,G18) -> TRUE | AK18: =_xlfn.CONCAT(B18," :",G18) -> Lakshmi Iyer :Training Specialist | AL18: =LEN(S18) -> 4 | AM18: =_xlfn.CONCAT(K18,"EXP") -> 6EXP | AN18: =_xlfn.NUMBERVALUE(LEFT(AM18,1)) -> 6 | AO18: =REPLACE(AM18,2,3,"Exprience") -> 6Exprience | AQ18: =RIGHT(AM18,3) -> EXP
A19: EMP117 | B19: Aditya Kapoor | C19: Aditya | D19: aapoor | E19: IT | F19: =LOWER(G19) -> cloud architect | G19: Cloud Architect | H19: Male | I19: 37 | J19: 2016-03-20 | K19: =DATEDIF(J19,TODAY(),"Y") -> 10 | L19: Noida | M19: 110000 | N19: 44000 | O19: =M19*0.2 -> 22000 | P19: =M19+N19+O19 -> 176000 | Q19: =P19*0.1 -> 17600 | R19: =P19-Q19 -> 158400 | S19: Outstanding | T19: 5 | U19: =IF(T19>=4,P19*0.05,P19*0.02) -> 8800 | V19: =LOWER(LEFT(B19,FIND(" ",B19)-1))&"."&LOWER(MID(B19,FIND(" ",B19)+1,100))&"@company.com" -> aditya.kapoor@company.com | W19: +91-9800000215 | X19: =TEXT(J19,"MMM-YYYY") -> Mar-2016 | Y19: =IF(M19>=100000,"Executive",IF(M19>=80000,"Senior",IF(M19>=60000,"Mid-Level","Junior"))) -> Executive | Z19: =UPPER(B19) -> ADITYA KAPOOR | AA19: =LOWER(V19) -> aditya.kapoor@company.com | AB19: =PROPER(G19) -> Cloud Architect | AC19: =BAHTTEXT(T19) -> ห้าบาทถ้วน | AD19: =LEFT(B19,1) -> A | AE19: =CODE(AD19) -> 65 | AF19: =CHAR(AE19) -> A | AI19: =DOLLAR(AE19) -> ₹ 65.00 | AJ19: =EXACT(AB19,G19) -> TRUE | AK19: =_xlfn.CONCAT(B19," :",G19) -> Aditya Kapoor :Cloud Architect | AL19: =LEN(S19) -> 11 | AM19: =_xlfn.CONCAT(K19,"EXP") -> 10EXP | AN19: =_xlfn.NUMBERVALUE(LEFT(AM19,1)) -> 1 | AO19: =REPLACE(AM19,2,3,"Exprience") -> 1ExprienceP | AQ19: =RIGHT(AM19,3) -> EXP
A20: EMP118 | B20: Nisha Saxena | C20: Nisha | D20: naxena | E20: Marketing | F20: =LOWER(G20) -> seo specialist | G20: SEO Specialist | H20: Female | I20: 26 | J20: 2023-01-09 | K20: =DATEDIF(J20,TODAY(),"Y") -> 3 | L20: Agra | M20: 47000 | N20: 18800 | O20: =M20*0.2 -> 9400 | P20: =M20+N20+O20 -> 75200 | Q20: =P20*0.1 -> 7520 | R20: =P20-Q20 -> 67680 | S20: Average | T20: 2 | U20: =IF(T20>=4,P20*0.05,P20*0.02) -> 1504 | V20: =LOWER(LEFT(B20,FIND(" ",B20)-1))&"."&LOWER(MID(B20,FIND(" ",B20)+1,100))&"@company.com" -> nisha.saxena@company.com | W20: +91-9800000228 | X20: =TEXT(J20,"MMM-YYYY") -> Jan-2023 | Y20: =IF(M20>=100000,"Executive",IF(M20>=80000,"Senior",IF(M20>=60000,"Mid-Level","Junior"))) -> Junior | Z20: =UPPER(B20) -> NISHA SAXENA | AA20: =LOWER(V20) -> nisha.saxena@company.com | AB20: =PROPER(G20) -> Seo Specialist | AC20: =BAHTTEXT(T20) -> สองบาทถ้วน | AD20: =LEFT(B20,1) -> N | AE20: =CODE(AD20) -> 78 | AF20: =CHAR(AE20) -> N | AI20: =DOLLAR(AE20) -> ₹ 78.00 | AJ20: =EXACT(AB20,G20) -> FALSE | AK20: =_xlfn.CONCAT(B20," :",G20) -> Nisha Saxena :SEO Specialist | AL20: =LEN(S20) -> 7 | AM20: =_xlfn.CONCAT(K20,"EXP") -> 3EXP | AN20: =_xlfn.NUMBERVALUE(LEFT(AM20,1)) -> 3 | AO20: =REPLACE(AM20,2,3,"Exprience") -> 3Exprience | AQ20: =RIGHT(AM20,3) -> EXP
... A32: EMP130 | B32: Deepa Krishnan | C32: Deepa | D32: drishnan | E32: Marketing | F32: =LOWER(G32) -> digital marketing mgr | G32: Digital Marketing Mgr | H32: Female | I32: 36 | J32: 2017-07-14 | K32: =DATEDIF(J32,TODAY(),"Y") -> 8 | L32: Chennai | M32: 83000 | N32: 33200 | O32: =M32*0.2 -> 16600 | P32: =M32+N32+O32 -> 132800 | Q32: =P32*0.1 -> 13280 | R32: =P32-Q32 -> 119520 | S32: Excellent | T32: 4 | U32: =IF(T32>=4,P32*0.05,P32*0.02) -> 6640 | V32: =LOWER(LEFT(B32,FIND(" ",B32)-1))&"."&LOWER(MID(B32,FIND(" ",B32)+1,100))&"@company.com" -> deepa.krishnan@company.com | W32: +91-9800000384 | X32: =TEXT(J32,"MMM-YYYY") -> Jul-2017 | Y32: =IF(M32>=100000,"Executive",IF(M32>=80000,"Senior",IF(M32>=60000,"Mid-Level","Junior"))) -> Senior | Z32: =UPPER(B32) -> DEEPA KRISHNAN | AA32: =LOWER(V32) -> deepa.krishnan@company.com | AB32: =PROPER(G32) -> Digital Marketing Mgr | AC32: =BAHTTEXT(T32) -> สี่บาทถ้วน | AD32: =LEFT(B32,1) -> D | AE32: =CODE(AD32) -> 68 | AF32: =CHAR(AE32) -> D | AI32: =DOLLAR(AE32) -> ₹ 68.00 | AJ32: =EXACT(AB32,G32) -> TRUE | AK32: =_xlfn.CONCAT(B32," :",G32) -> Deepa Krishnan :Digital Marketing Mgr | AL32: =LEN(S32) -> 9 | AM32: =_xlfn.CONCAT(K32,"EXP") -> 8EXP | AN32: =_xlfn.NUMBERVALUE(LEFT(AM32,1)) -> 8 | AO32: =REPLACE(AM32,2,3,"Exprience") -> 8Exprience | AQ32: =RIGHT(AM32,3) -> EXP

Sheet Sheet1
A1: Emp ID | B1: Full Name | C1: Department | D1: Designation | E1: Gender | F1: Age | G1: Date of Join | H1: Experience(Yrs) | I1: City | J1: Basic Salary | K1: HRA | L1: Allowances | M1: Gross Salary | N1: Tax (10%) | O1: Net Salary | P1: Performance | Q1: Rating (1-5) | R1: Bonus | S1: Email | T1: Phone | U1: Join Month | V1: Salary Band
A2: EMP101 | B2: Aarav Sharma | C2: IT | D2: software Engineer | E2: Male | F2: 28 | G2: 2019-03-15 | H2: =DATEDIF(G2,TODAY(),"Y") -> 7 | I2: Mumbai | J2: 65000 | K2: 26000 | L2: =J2*0.2 -> 13000 | M2: =J2+K2+L2 -> 104000 | N2: =M2*0.1 -> 10400 | O2: =M2-N2 -> 93600 | P2: Excellent | Q2: 4 | R2: =IF(Q2>=4,M2*0.05,M2*0.02) -> 5200 | S2: =LOWER(LEFT(B2,FIND(" ",B2)-1))&"."&LOWER(MID(B2,FIND(" ",B2)+1,100))&"@company.com" -> aarav.sharma@company.com | T2: +91-9800000007 | U2: =TEXT(G2,"MMM-YYYY") -> Mar-2019 | V2: =IF(J2>=100000,"Executive",IF(J2>=80000,"Senior",IF(J2>=60000,"Mid-Level","Junior"))) -> Mid-Level
A3: EMP102 | B3: Priya Patel | C3: HR | D3: HR Manager | E3: Female | F3: 35 | G3: 2017-06-01 | H3: =DATEDIF(G3,TODAY(),"Y") -> 8 | I3: Ahmedabad | J3: 72000 | K3: 28800 | L3: =J3*0.2 -> 14400 | M3: =J3+K3+L3 -> 115200 | N3: =M3*0.1 -> 11520 | O3: =M3-N3 -> 103680 | P3: Good | Q3: 3 | R3: =IF(Q3>=4,M3*0.05,M3*0.02) -> 2304 | S3: =LOWER(LEFT(B3,FIND(" ",B3)-1))&"."&LOWER(MID(B3,FIND(" ",B3)+1,100))&"@company.com" -> priya.patel@company.com | T3: +91-9800000020 | U3: =TEXT(G3,"MMM-YYYY") -> Jun-2017 | V3: =IF(J3>=100000,"Executive",IF(J3>=80000,"Senior",IF(J3>=60000,"Mid-Level","Junior"))) -> Mid-Level
A4: EMP103 | B4: Rohit Mehta | C4: Finance | D4: Financial Analyst | E4: Male | F4: 32 | G4: 2018-09-10 | H4: =DATEDIF(G4,TODAY(),"Y") -> 7 | I4: Delhi | J4: 68000 | K4: 27200 | L4: =J4*0.2 -> 13600 | M4: =J4+K4+L4 -> 108800 | N4: =M4*0.1 -> 10880 | O4: =M4-N4 -> 97920 | P4: Excellent | Q4: 5 | R4: =IF(Q4>=4,M4*0.05,M4*0.02) -> 5440 | S4: =LOWER(LEFT(B4,FIND(" ",B4)-1))&"."&LOWER(MID(B4,FIND(" ",B4)+1,100))&"@company.com" -> rohit.mehta@company.com | T4: +91-9800000033 | U4: =TEXT(G4,"MMM-YYYY") -> Sep-2018 | V4: =IF(J4>=100000,"Executive",IF(J4>=80000,"Senior",IF(J4>=60000,"Mid-Level","Junior"))) -> Mid-Level
A5: EMP104 | B5: Sneha Reddy | C5: IT | D5: Full Stack Developer | E5: Female | F5: 26 | G5: 2021-01-20 | H5: =DATEDIF(G5,TODAY(),"Y") -> 5 | I5: Hyderabad | J5: 70000 | K5: 28000 | L5: =J5*0.2 -> 14000 | M5: =J5+K5+L5 -> 112000 | N5: =M5*0.1 -> 11200 | O5: =M5-N5 -> 100800 | P5: Good | Q5: 4 | R5: =IF(Q5>=4,M5*0.05,M5*0.02) -> 5600 | S5: =LOWER(LEFT(B5,FIND(" ",B5)-1))&"."&LOWER(MID(B5,FIND(" ",B5)+1,100))&"@company.com" -> sneha.reddy@company.com | T5: +91-9800000046 | U5: =TEXT(G5,"MMM-YYYY") -> Jan-2021 | V5: =IF(J5>=100000,"Executive",IF(J5>=80000,"Senior",IF(J5>=60000,"Mid-Level","Junior"))) -> Mid-Level | X5: EMPLOPYEE ID | Y5: EMP119
A6: EMP105 | B6: Vikram Singh | C6: Sales | D6: Sales Executive | E6: Male | F6: 30 | G6: 2020-07-05 | H6: =DATEDIF(G6,TODAY(),"Y") -> 5 | I6: Jaipur | J6: 45000 | K6: 18000 | L6: =J6*0.2 -> 9000 | M6: =J6+K6+L6 -> 72000 | N6: =M6*0.1 -> 7200 | O6: =M6-N6 -> 64800 | P6: Average | Q6: 3 | R6: =IF(Q6>=4,M6*0.05,M6*0.02) -> 1440 | S6: =LOWER(LEFT(B6,FIND(" ",B6)-1))&"."&LOWER(MID(B6,FIND(" ",B6)+1,100))&"@company.com" -> vikram.singh@company.com | T6: +91-9800000059 | U6: =TEXT(G6,"MMM-YYYY") -> Jul-2020 | V6: =IF(J6>=100000,"Executive",IF(J6>=80000,"Senior",IF(J6>=60000,"Mid-Level","Junior"))) -> Junior | X6: EMPLOYEE NAME | Y6: =IFERROR(VLOOKUP(Y5,A1:V31,2,FALSE),"Not Found") -> Rajesh Bose
A7: EMP106 | B7: Kavya Nair | C7: Marketing | D7: Marketing Manager | E7: Female | F7: 38 | G7: 2015-11-12 | H7: =DATEDIF(G7,TODAY(),"Y") -> 10 | I7: Kochi | J7: 80000 | K7: 32000 | L7: =J7*0.2 -> 16000 | M7: =J7+K7+L7 -> 128000 | N7: =M7*0.1 -> 12800 | O7: =M7-N7 -> 115200 | P7: Excellent | Q7: 5 | R7: =IF(Q7>=4,M7*0.05,M7*0.02) -> 6400 | S7: =LOWER(LEFT(B7,FIND(" ",B7)-1))&"."&LOWER(MID(B7,FIND(" ",B7)+1,100))&"@company.com" -> kavya.nair@company.com | T7: +91-9800000072 | U7: =TEXT(G7,"MMM-YYYY") -> Nov-2015 | V7: =IF(J7>=100000,"Executive",IF(J7>=80000,"Senior",IF(J7>=60000,"Mid-Level","Junior"))) -> Senior | X7: Department | Y7: =IFERROR(VLOOKUP(Y5,A1:V31,3,),"Not Found") -> Finance
A8: EMP107 | B8: Arjun Kumar | C8: IT | D8: Data Scientist | E8: Male | F8: 29 | G8: 2020-04-18 | H8: =DATEDIF(G8,TODAY(),"Y") -> 6 | I8: Bangalore | J8: 90000 | K8: 36000 | L8: =J8*0.2 -> 18000 | M8: =J8+K8+L8 -> 144000 | N8: =M8*0.1 -> 14400 | O8: =M8-N8 -> 129600 | P8: Outstanding | Q8: 5 | R8: =IF(Q8>=4,M8*0.05,M8*0.02) -> 7200 | S8: =LOWER(LEFT(B8,FIND(" ",B8)-1))&"."&LOWER(MID(B8,FIND(" ",B8)+1,100))&"@company.com" -> arjun.kumar@company.com | T8: +91-9800000085 | U8: =TEXT(G8,"MMM-YYYY") -> Apr-2020 | V8: =IF(J8>=100000,"Executive",IF(J8>=80000,"Senior",IF(J8>=60000,"Mid-Level","Junior"))) -> Senior | X8: BASIC SALARY | Y8: =IFERROR(VLOOKUP(Y5,A1:V32,10,),"Not Found") -> 150000
A9: EMP108 | B9: Divya Verma | C9: Finance | D9: Accountant | E9: Female | F9: 27 | G9: 2022-02-28 | H9: =DATEDIF(G9,TODAY(),"Y") -> 4 | I9: Pune | J9: 55000 | K9: 22000 | L9: =J9*0.2 -> 11000 | M9: =J9+K9+L9 -> 88000 | N9: =M9*0.1 -> 8800 | O9: =M9-N9 -> 79200 | P9: Good | Q9: 3 | R9: =IF(Q9>=4,M9*0.05,M9*0.02) -> 1760 | S9: =LOWER(LEFT(B9,FIND(" ",B9)-1))&"."&LOWER(MID(B9,FIND(" ",B9)+1,100))&"@company.com" -> divya.verma@company.com | T9: +91-9800000098 | U9: =TEXT(G9,"MMM-YYYY") -> Feb-2022 | V9: =IF(J9>=100000,"Executive",IF(J9>=80000,"Senior",IF(J9>=60000,"Mid-Level","Junior"))) -> Junior | X9: Net Salary | Y9: =IFERROR(VLOOKUP(Y5,A1:V31,15,),"Not Found") -> 216000
A10: EMP109 | B10: Ravi Tiwari | C10: Sales | D10: Regional Manager | E10: Male | F10: 42 | G10: 2013-08-30 | H10: =DATEDIF(G10,TODAY(),"Y") -> 12 | I10: Lucknow | J10: 95000 | K10: 38000 | L10: =J10*0.2 -> 19000 | M10: =J10+K10+L10 -> 152000 | N10: =M10*0.1 -> 15200 | O10: =M10-N10 -> 136800 | P10: Outstanding | Q10: 5 | R10: =IF(Q10>=4,M10*0.05,M10*0.02) -> 7600 | S10: =LOWER(LEFT(B10,FIND(" ",B10)-1))&"."&LOWER(MID(B10,FIND(" ",B10)+1,100))&"@company.com" -> ravi.tiwari@company.com | T10: +91-9800000111 | U10: =TEXT(G10,"MMM-YYYY") -> Aug-2013 | V10: =IF(J10>=100000,"Executive",IF(J10>=80000,"Senior",IF(J10>=60000,"Mid-Level","Junior"))) -> Senior
A11: EMP110 | B11: Anjali Mishra | C11: HR | D11: Recruiter | E11: Female | F11: 25 | G11: 2023-03-01 | H11: =DATEDIF(G11,TODAY(),"Y") -> 3 | I11: Bhopal | J11: 40000 | K11: 16000 | L11: =J11*0.2 -> 8000 | M11: =J11+K11+L11 -> 64000 | N11: =M11*0.1 -> 6400 | O11: =M11-N11 -> 57600 | P11: Average | Q11: 2 | R11: =IF(Q11>=4,M11*0.05,M11*0.02) -> 1280 | S11: =LOWER(LEFT(B11,FIND(" ",B11)-1))&"."&LOWER(MID(B11,FIND(" ",B11)+1,100))&"@company.com" -> anjali.mishra@company.com | T11: +91-9800000124 | U11: =TEXT(G11,"MMM-YYYY") -> Mar-2023 | V11: =IF(J11>=100000,"Executive",IF(J11>=80000,"Senior",IF(J11>=60000,"Mid-Level","Junior"))) -> Junior
A12: EMP111 | B12: Suresh Gupta | C12: IT | D12: DevOps Engineer | E12: Male | F12: 33 | G12: 2019-05-22 | H12: =DATEDIF(G12,TODAY(),"Y") -> 6 | I12: Chennai | J12: 78000 | K12: 31200 | L12: =J12*0.2 -> 15600 | M12: =J12+K12+L12 -> 124800 | N12: =M12*0.1 -> 12480 | O12: =M12-N12 -> 112320 | P12: Good | Q12: 4 | R12: =IF(Q12>=4,M12*0.05,M12*0.02) -> 6240 | S12: =LOWER(LEFT(B12,FIND(" ",B12)-1))&"."&LOWER(MID(B12,FIND(" ",B12)+1,100))&"@company.com" -> suresh.gupta@company.com | T12: +91-9800000137 | U12: =TEXT(G12,"MMM-YYYY") -> May-2019 | V12: =IF(J12>=100000,"Executive",IF(J12>=80000,"Senior",IF(J12>=60000,"Mid-Level","Junior"))) -> Mid-Level
A13: EMP112 | B13: Meera Joshi | C13: Marketing | D13: Content Strategist | E13: Female | F13: 29 | G13: 2021-09-14 | H13: =DATEDIF(G13,TODAY(),"Y") -> 4 | I13: Indore | J13: 52000 | K13: 20800 | L13: =J13*0.2 -> 10400 | M13: =J13+K13+L13 -> 83200 | N13: =M13*0.1 -> 8320 | O13: =M13-N13 -> 74880 | P13: Good | Q13: 3 | R13: =IF(Q13>=4,M13*0.05,M13*0.02) -> 1664 | S13: =LOWER(LEFT(B13,FIND(" ",B13)-1))&"."&LOWER(MID(B13,FIND(" ",B13)+1,100))&"@company.com" -> meera.joshi@company.com | T13: +91-9800000150 | U13: =TEXT(G13,"MMM-YYYY") -> Sep-2021 | V13: =IF(J13>=100000,"Executive",IF(J13>=80000,"Senior",IF(J13>=60000,"Mid-Level","Junior"))) -> Junior
A14: EMP113 | B14: Nikhil Pandey | C14: Finance | D14: Senior Accountant | E14: Male | F14: 36 | G14: 2016-12-03 | H14: =DATEDIF(G14,TODAY(),"Y") -> 9 | I14: Varanasi | J14: 74000 | K14: 29600 | L14: =J14*0.2 -> 14800 | M14: =J14+K14+L14 -> 118400 | N14: =M14*0.1 -> 11840 | O14: =M14-N14 -> 106560 | P14: Excellent | Q14: 4 | R14: =IF(Q14>=4,M14*0.05,M14*0.02) -> 5920 | S14: =LOWER(LEFT(B14,FIND(" ",B14)-1))&"."&LOWER(MID(B14,FIND(" ",B14)+1,100))&"@company.com" -> nikhil.pandey@company.com | T14: +91-9800000163 | U14: =TEXT(G14,"MMM-YYYY") -> Dec-2016 | V14: =IF(J14>=100000,"Executive",IF(J14>=80000,"Senior",IF(J14>=60000,"Mid-Level","Junior"))) -> Mid-Level
A15: EMP114 | B15: Pooja Yadav | C15: IT | D15: QA Engineer | E15: Female | F15: 27 | G15: 2022-06-17 | H15: =DATEDIF(G15,TODAY(),"Y") -> 3 | I15: Nagpur | J15: 58000 | K15: 23200 | L15: =J15*0.2 -> 11600 | M15: =J15+K15+L15 -> 92800 | N15: =M15*0.1 -> 9280 | O15: =M15-N15 -> 83520 | P15: Average | Q15: 3 | R15: =IF(Q15>=4,M15*0.05,M15*0.02) -> 1856 | S15: =LOWER(LEFT(B15,FIND(" ",B15)-1))&"."&LOWER(MID(B15,FIND(" ",B15)+1,100))&"@company.com" -> pooja.yadav@company.com | T15: +91-9800000176 | U15: =TEXT(G15,"MMM-YYYY") -> Jun-2022 | V15: =IF(J15>=100000,"Executive",IF(J15>=80000,"Senior",IF(J15>=60000,"Mid-Level","Junior"))) -> Junior
A16: EMP115 | B16: Manoj Desai | C16: Sales | D16: Sales Manager | E16: Male | F16: 40 | G16: 2014-10-25 | H16: =DATEDIF(G16,TODAY(),"Y") -> 11 | I16: Surat | J16: 88000 | K16: 35200 | L16: =J16*0.2 -> 17600 | M16: =J16+K16+L16 -> 140800 | N16: =M16*0.1 -> 14080 | O16: =M16-N16 -> 126720 | P16: Outstanding | Q16: 5 | R16: =IF(Q16>=4,M16*0.05,M16*0.02) -> 7040 | S16: =LOWER(LEFT(B16,FIND(" ",B16)-1))&"."&LOWER(MID(B16,FIND(" ",B16)+1,100))&"@company.com" -> manoj.desai@company.com | T16: +91-9800000189 | U16: =TEXT(G16,"MMM-YYYY") -> Oct-2014 | V16: =IF(J16>=100000,"Executive",IF(J16>=80000,"Senior",IF(J16>=60000,"Mid-Level","Junior"))) -> Senior
A17: EMP116 | B17: Lakshmi Iyer | C17: HR | D17: Training Specialist | E17: Female | F17: 31 | G17: 2019-07-08 | H17: =DATEDIF(G17,TODAY(),"Y") -> 6 | I17: Madurai | J17: 62000 | K17: 24800 | L17: =J17*0.2 -> 12400 | M17: =J17+K17+L17 -> 99200 | N17: =M17*0.1 -> 9920 | O17: =M17-N17 -> 89280 | P17: Good | Q17: 4 | R17: =IF(Q17>=4,M17*0.05,M17*0.02) -> 4960 | S17: =LOWER(LEFT(B17,FIND(" ",B17)-1))&"."&LOWER(MID(B17,FIND(" ",B17)+1,100))&"@company.com" -> lakshmi.iyer@company.com | T17: +91-9800000202 | U17: =TEXT(G17,"MMM-YYYY") -> Jul-2019 | V17: =IF(J17>=100000,"Executive",IF(J17>=80000,"Senior",IF(J17>=60000,"Mid-Level","Junior"))) -> Mid-Level
A18: EMP117 | B18: Aditya Kapoor | C18: IT | D18: Cloud Architect | E18: Male | F18: 37 | G18: 2016-03-20 | H18: =DATEDIF(G18,TODAY(),"Y") -> 10 | I18: Noida | J18: 110000 | K18: 44000 | L18: =J18*0.2 -> 22000 | M18: =J18+K18+L18 -> 176000 | N18: =M18*0.1 -> 17600 | O18: =M18-N18 -> 158400 | P18: Outstanding | Q18: 5 | R18: =IF(Q18>=4,M18*0.05,M18*0.02) -> 8800 | S18: =LOWER(LEFT(B18,FIND(" ",B18)-1))&"."&LOWER(MID(B18,FIND(" ",B18)+1,100))&"@company.com" -> aditya.kapoor@company.com | T18: +91-9800000215 | U18: =TEXT(G18,"MMM-YYYY") -> Mar-2016 | V18: =IF(J18>=100000,"Executive",IF(J18>=80000,"Senior",IF(J18>=60000,"Mid-Level","Junior"))) -> Executive
A19: EMP118 | B19: Nisha Saxena | C19: Marketing | D19: SEO Specialist | E19: Female | F19: 26 | G19: 2023-01-09 | H19: =DATEDIF(G19,TODAY(),"Y") -> 3 | I19: Agra | J19: 47000 | K19: 18800 | L19: =J19*0.2 -> 9400 | M19: =J19+K19+L19 -> 75200 | N19: =M19*0.1 -> 7520 | O19: =M19-N19 -> 67680 | P19: Average | Q19: 2 | R19: =IF(Q19>=4,M19*0.05,M19*0.02) -> 1504 | S19: =LOWER(LEFT(B19,FIND(" ",B19)-1))&"."&LOWER(MID(B19,FIND(" ",B19)+1,100))&"@company.com" -> nisha.saxena@company.com | T19: +91-9800000228 | U19: =TEXT(G19,"MMM-YYYY") -> Jan-2023 | V19: =IF(J19>=100000,"Executive",IF(J19>=80000,"Senior",IF(J19>=60000,"Mid-Level","Junior"))) -> Junior
A20: EMP119 | B20: Rajesh Bose | C20: Finance | D20: CFO | E20: Male | F20: 50 | G20: 2010-04-15 | H20: =DATEDIF(G20,TODAY(),"Y") -> 16 | I20: Kolkata | J20: 150000 | K20: 60000 | L20: =J20*0.2 -> 30000 | M20: =J20+K20+L20 -> 240000 | N20: =M20*0.1 -> 24000 | O20: =M20-N20 -> 216000 | P20: Outstanding | Q20: 5 | R20: =IF(Q20>=4,M20*0.05,M20*0.02) -> 12000 | S20: =LOWER(LEFT(B20,FIND(" ",B20)-1))&"."&LOWER(MID(B20,FIND(" ",B20)+1,100))&"@company.com" -> rajesh.bose@company.com | T20: +91-9800000241 | U20: =TEXT(G20,"MMM-YYYY") -> Apr-2010 | V20: =IF(J20>=100000,"Executive",IF(J20>=80000,"Senior",IF(J20>=60000,"Mid-Level","Junior"))) -> Executive
A21: EMP120 | B21: Simran Kaur | C21: IT | D21: Mobile Developer | E21: Female | F21: 28 | G21: 2021-11-30 | H21: =DATEDIF(G21,TODAY(),"Y") -> 4 | I21: Chandigarh | J21: 67000 | K21: 26800 | L21: =J21*0.2 -> 13400 | M21: =J21+K21+L21 -> 107200 | N21: =M21*0.1 -> 10720 | O21: =M21-N21 -> 96480 | P21: Good | Q21: 4 | R21: =IF(Q21>=4,M21*0.05,M21*0.02) -> 5360 | S21: =LOWER(LEFT(B21,FIND(" ",B21)-1))&"."&LOWER(MID(B21,FIND(" ",B21)+1,100))&"@company.com" -> simran.kaur@company.com | T21: +91-9800000254 | U21: =TEXT(G21,"MMM-YYYY") -> Nov-2021 | V21: =IF(J21>=100000,"Executive",IF(J21>=80000,"Senior",IF(J21>=60000,"Mid-Level","Junior"))) -> Mid-Level
... A31: EMP130 | B31: Deepa Krishnan | C31: Marketing | D31: Digital Marketing Mgr | E31: Female | F31: 36 | G31: 2017-07-14 | H31: =DATEDIF(G31,TODAY(),"Y") -> 8 | I31: Chennai | J31: 83000 | K31: 33200 | L31: =J31*0.2 -> 16600 | M31: =J31+K31+L31 -> 132800 | N31: =M31*0.1 -> 13280 | O31: =M31-N31 -> 119520 | P31: Excellent | Q31: 4 | R31: =IF(Q31>=4,M31*0.05,M31*0.02) -> 6640 | S31: =LOWER(LEFT(B31,FIND(" ",B31)-1))&"."&LOWER(MID(B31,FIND(" ",B31)+1,100))&"@company.com" -> deepa.krishnan@company.com | T31: +91-9800000384 | U31: =TEXT(G31,"MMM-YYYY") -> Jul-2017 | V31: =IF(J31>=100000,"Executive",IF(J31>=80000,"Senior",IF(J31>=60000,"Mid-Level","Junior"))) -> Senior

Sheet Sheet2
A1: Emp ID | B1: EMP101 | C1: EMP102 | D1: EMP103 | E1: EMP104 | F1: EMP105 | G1: EMP106 | H1: EMP107 | I1: EMP108 | J1: EMP109 | K1: EMP110 | L1: EMP111 | M1: EMP112 | N1: EMP113 | O1: EMP114 | P1: EMP115 | Q1: EMP116 | R1: EMP117 | S1: EMP118 | T1: EMP119 | U1: EMP120 | V1: EMP121 | W1: EMP122 | X1: EMP123 | Y1: EMP124 | Z1: EMP125 | AA1: EMP126 | AB1: EMP127 | AC1: EMP128 | AD1: EMP129 | AE1: EMP130
A2: Full Name | B2: Aarav Sharma | C2: Priya Patel | D2: Rohit Mehta | E2: Sneha Reddy | F2: Vikram Singh | G2: Kavya Nair | H2: Arjun Kumar | I2: Divya Verma | J2: Ravi Tiwari | K2: Anjali Mishra | L2: Suresh Gupta | M2: Meera Joshi | N2: Nikhil Pandey | O2: Pooja Yadav | P2: Manoj Desai | Q2: Lakshmi Iyer | R2: Aditya Kapoor | S2: Nisha Saxena | T2: Rajesh Bose | U2: Simran Kaur | V2: Tarun Bhatt | W2: Uma Shetty | X2: Varun Malhotra | Y2: Waqar Hussain | Z2: Yamini Rao | AA2: Zara Ahmed | AB2: Ajay Choudhary | AC2: Bharti Trivedi | AD2: Chetan Rawat | AE2: Deepa Krishnan
A3: Department | B3: IT | C3: HR | D3: Finance | E3: IT | F3: Sales | G3: Marketing | H3: IT | I3: Finance | J3: Sales | K3: HR | L3: IT | M3: Marketing | N3: Finance | O3: IT | P3: Sales | Q3: HR | R3: IT | S3: Marketing | T3: Finance | U3: IT | V3: Sales | W3: HR | X3: IT | Y3: Marketing | Z3: Finance | AA3: IT | AB3: Sales | AC3: Finance | AD3: IT | AE3: Marketing
A4: Designation | B4: software Engineer | C4: HR Manager | D4: Financial Analyst | E4: Full Stack Developer | F4: Sales Executive | G4: Marketing Manager | H4: Data Scientist | I4: Accountant | J4: Regional Manager | K4: Recruiter | L4: DevOps Engineer | M4: Content Strategist | N4: Senior Accountant | O4: QA Engineer | P4: Sales Manager | Q4: Training Specialist | R4: Cloud Architect | S4: SEO Specialist | T4: CFO | U4: Mobile Developer | V4: Sales Executive | W4: HR Director | X4: Backend Developer | Y4: Brand Manager | Z4: Tax Consultant | AA4: Cyber Security Analyst | AB4: Business Developer | AC4: Payroll Specialist | AD4: Machine Learning Eng | AE4: Digital Marketing Mgr
A5: Gender | B5: Male | C5: Female | D5: Male | E5: Female | F5: Male | G5: Female | H5: Male | I5: Female | J5: Male | K5: Female | L5: Male | M5: Female | N5: Male | O5: Female | P5: Male | Q5: Female | R5: Male | S5: Female | T5: Male | U5: Female | V5: Male | W5: Female | X5: Male | Y5: Male | Z5: Female | AA5: Female | AB5: Male | AC5: Female | AD5: Male | AE5: Female
A6: Age | B6: 28 | C6: 35 | D6: 32 | E6: 26 | F6: 30 | G6: 38 | H6: 29 | I6: 27 | J6: 42 | K6: 25 | L6: 33 | M6: 29 | N6: 36 | O6: 27 | P6: 40 | Q6: 31 | R6: 37 | S6: 26 | T6: 50 | U6: 28 | V6: 24 | W6: 45 | X6: 31 | Y6: 34 | Z6: 30 | AA6: 29 | AB6: 33 | AC6: 28 | AD6: 30 | AE6: 36
A7: Date of Join | B7: 2019-03-15 | C7: 2017-06-01 | D7: 2018-09-10 | E7: 2021-01-20 | F7: 2020-07-05 | G7: 2015-11-12 | H7: 2020-04-18 | I7: 2022-02-28 | J7: 2013-08-30 | K7: 2023-03-01 | L7: 2019-05-22 | M7: 2021-09-14 | N7: 2016-12-03 | O7: 2022-06-17 | P7: 2014-10-25 | Q7: 2019-07-08 | R7: 2016-03-20 | S7: 2023-01-09 | T7: 2010-04-15 | U7: 2021-11-30 | V7: 2024-01-15 | W7: 2011-09-01 | X7: 2020-08-12 | Y7: 2018-02-22 | Z7: 2019-10-07 | AA7: 2020-12-01 | AB7: 2018-06-18 | AC7: 2022-04-05 | AD7: 2021-03-25 | AE7: 2017-07-14
A8: Experience(Yrs) | B8: =DATEDIF(B7,TODAY(),"Y") -> 7 | C8: =DATEDIF(C7,TODAY(),"Y") -> 8 | D8: =DATEDIF(D7,TODAY(),"Y") -> 7 | E8: =DATEDIF(E7,TODAY(),"Y") -> 5 | F8: =DATEDIF(F7,TODAY(),"Y") -> 5 | G8: =DATEDIF(G7,TODAY(),"Y") -> 10 | H8: =DATEDIF(H7,TODAY(),"Y") -> 6 | I8: =DATEDIF(I7,TODAY(),"Y") -> 4 | ... AE8: =DATEDIF(AE7,TODAY(),"Y") -> 8
A9: City | B9: Mumbai | C9: Ahmedabad | D9: Delhi | E9: Hyderabad | F9: Jaipur | G9: Kochi | H9: Bangalore | I9: Pune | J9: Lucknow | K9: Bhopal | L9: Chennai | M9: Indore | N9: Varanasi | O9: Nagpur | P9: Surat | Q9: Madurai | R9: Noida | S9: Agra | T9: Kolkata | U9: Chandigarh | V9: Dehradun | W9: Mangalore | X9: Gurgaon | Y9: Lucknow | Z9: Vijayawada | AA9: Hyderabad | AB9: Patna | AC9: Jaipur | AD9: Pune | AE9: Chennai
A10: Basic Salary | B10: 65000 | C10: 72000 | D10: 68000 | E10: 70000 | F10: 45000 | G10: 80000 | H10: 90000 | I10: 55000 | J10: 95000 | K10: 40000 | L10: 78000 | M10: 52000 | N10: 74000 | O10: 58000 | P10: 88000 | Q10: 62000 | R10: 110000 | S10: 47000 | T10: 150000 | U10: 67000 | V10: 42000 | W10: 120000 | X10: 82000 | Y10: 77000 | Z10: 69000 | AA10: 85000 | AB10: 58000 | AC10: 61000 | AD10: 95000 | AE10: 83000
A11: HRA | B11: 26000 | C11: 28800 | D11: 27200 | E11: 28000 | F11: 18000 | G11: 32000 | H11: 36000 | I11: 22000 | J11: 38000 | K11: 16000 | L11: 31200 | M11: 20800 | N11: 29600 | O11: 23200 | P11: 35200 | Q11: 24800 | R11: 44000 | S11: 18800 | T11: 60000 | U11: 26800 | V11: 16800 | W11: 48000 | X11: 32800 | Y11: 30800 | Z11: 27600 | AA11: 34000 | AB11: 23200 | AC11: 24400 | AD11: 38000 | AE11: 33200
A12: Allowances | B12: =B10*0.2 -> 13000 | C12: =C10*0.2 -> 14400 | D12: =D10*0.2 -> 13600 | E12: =E10*0.2 -> 14000 | F12: =F10*0.2 -> 9000 | G12: =G10*0.2 -> 16000 | H12: =H10*0.2 -> 18000 | I12: =I10*0.2 -> 11000 | ... AE12: =AE10*0.2 -> 16600
A13: Gross Salary | B13: =B10+B11+B12 -> 104000 | C13: =C10+C11+C12 -> 115200 | D13: =D10+D11+D12 -> 108800 | E13: =E10+E11+E12 -> 112000 | F13: =F10+F11+F12 -> 72000 | G13: =G10+G11+G12 -> 128000 | H13: =H10+H11+H12 -> 144000 | I13: =I10+I11+I12 -> 88000 | ... AE13: =AE10+AE11+AE12 -> 132800
A14: Tax (10%) | B14: =B13*0.1 -> 10400 | C14: =C13*0.1 -> 11520 | D14: =D13*0.1 -> 10880 | E14: =E13*0.1 -> 11200 | F14: =F13*0.1 -> 7200 | G14: =G13*0.1 -> 12800 | H14: =H13*0.1 -> 14400 | I14: =I13*0.1 -> 8800 | ... AE14: =AE13*0.1 -> 13280
A15: Net Salary | B15: =B13-B14 -> 93600 | C15: =C13-C14 -> 103680 | D15: =D13-D14 -> 97920 | E15: =E13-E14 -> 100800 | F15: =F13-F14 -> 64800 | G15: =G13-G14 -> 115200 | H15: =H13-H14 -> 129600 | I15: =I13-I14 -> 79200 | ... AE15: =AE13-AE14 -> 119520
A16: Performance | B16: Excellent | C16: Good | D16: Excellent | E16: Good | F16: Average | G16: Excellent | H16: Outstanding | I16: Good | J16: Outstanding | K16: Average | L16: Good | M16: Good | N16: Excellent | O16: Average | P16: Outstanding | Q16: Good | R16: Outstanding | S16: Average | T16: Outstanding | U16: Good | V16: Average | W16: Outstanding | X16: Good | Y16: Excellent | Z16: Good | AA16: Outstanding | AB16: Average | AC16: Good | AD16: Outstanding | AE16: Excellent
A17: Rating (1-5) | B17: 4 | C17: 3 | D17: 5 | E17: 4 | F17: 3 | G17: 5 | H17: 5 | I17: 3 | J17: 5 | K17: 2 | L17: 4 | M17: 3 | N17: 4 | O17: 3 | P17: 5 | Q17: 4 | R17: 5 | S17: 2 | T17: 5 | U17: 4 | V17: 2 | W17: 5 | X17: 4 | Y17: 4 | Z17: 4 | AA17: 5 | AB17: 3 | AC17: 4 | AD17: 5 | AE17: 4
A18: Bonus | B18: =IF(B17>=4,B13*0.05,B13*0.02) -> 5200 | C18: =IF(C17>=4,C13*0.05,C13*0.02) -> 2304 | D18: =IF(D17>=4,D13*0.05,D13*0.02) -> 5440 | E18: =IF(E17>=4,E13*0.05,E13*0.02) -> 5600 | F18: =IF(F17>=4,F13*0.05,F13*0.02) -> 1440 | G18: =IF(G17>=4,G13*0.05,G13*0.02) -> 6400 | H18: =IF(H17>=4,H13*0.05,H13*0.02) -> 7200 | I18: =IF(I17>=4,I13*0.05,I13*0.02) -> 1760 | ... AE18: =IF(AE17>=4,AE13*0.05,AE13*0.02) -> 6640
A19: Email | B19: =LOWER(LEFT(B2,FIND(" ",B2)-1))&"."&LOWER(MID(B2,FIND(" ",B2)+1,100))&"@company.com" -> aarav.sharma@company.com | C19: =LOWER(LEFT(C2,FIND(" ",C2)-1))&"."&LOWER(MID(C2,FIND(" ",C2)+1,100))&"@company.com" -> priya.patel@company.com | D19: =LOWER(LEFT(D2,FIND(" ",D2)-1))&"."&LOWER(MID(D2,FIND(" ",D2)+1,100))&"@company.com" -> rohit.mehta@company.com | E19: =LOWER(LEFT(E2,FIND(" ",E2)-1))&"."&LOWER(MID(E2,FIND(" ",E2)+1,100))&"@company.com" -> sneha.reddy@company.com | F19: =LOWER(LEFT(F2,FIND(" ",F2)-1))&"."&LOWER(MID(F2,FIND(" ",F2)+1,100))&"@company.com" -> vikram.singh@company.com | G19: =LOWER(LEFT(G2,FIND(" ",G2)-1))&"."&LOWER(MID(G2,FIND(" ",G2)+1,100))&"@company.com" -> kavya.nair@company.com | H19: =LOWER(LEFT(H2,FIND(" ",H2)-1))&"."&LOWER(MID(H2,FIND(" ",H2)+1,100))&"@company.com" -> arjun.kumar@company.com | I19: =LOWER(LEFT(I2,FIND(" ",I2)-1))&"."&LOWER(MID(I2,FIND(" ",I2)+1,100))&"@company.com" -> divya.verma@company.com | ... AE19: =LOWER(LEFT(AE2,FIND(" ",AE2)-1))&"."&LOWER(MID(AE2,FIND(" ",AE2)+1,100))&"@company.com" -> deepa.krishnan@company.com
A20: Phone | B20: +91-9800000007 | C20: +91-9800000020 | D20: +91-9800000033 | E20: +91-9800000046 | F20: +91-9800000059 | G20: +91-9800000072 | H20: +91-9800000085 | I20: +91-9800000098 | J20: +91-9800000111 | K20: +91-9800000124 | L20: +91-9800000137 | M20: +91-9800000150 | N20: +91-9800000163 | O20: +91-9800000176 | P20: +91-9800000189 | Q20: +91-9800000202 | R20: +91-9800000215 | S20: +91-9800000228 | T20: +91-9800000241 | U20: +91-9800000254 | V20: +91-9800000267 | W20: +91-9800000280 | X20: +91-9800000293 | Y20: +91-9800000306 | Z20: +91-9800000319 | AA20: +91-9800000332 | AB20: +91-9800000345 | AC20: +91-9800000358 | AD20: +91-9800000371 | AE20: +91-9800000384
A21: Join Month | B21: =TEXT(B7,"MMM-YYYY") -> Mar-2019 | C21: =TEXT(C7,"MMM-YYYY") -> Jun-2017 | D21: =TEXT(D7,"MMM-YYYY") -> Sep-2018 | E21: =TEXT(E7,"MMM-YYYY") -> Jan-2021 | F21: =TEXT(F7,"MMM-YYYY") -> Jul-2020 | G21: =TEXT(G7,"MMM-YYYY") -> Nov-2015 | H21: =TEXT(H7,"MMM-YYYY") -> Apr-2020 | I21: =TEXT(I7,"MMM-YYYY") -> Feb-2022 | ... AE21: =TEXT(AE7,"MMM-YYYY") -> Jul-2017
A22: Salary Band | B22: =IF(B10>=100000,"Executive",IF(B10>=80000,"Senior",IF(B10>=60000,"Mid-Level","Junior"))) -> Mid-Level | C22: =IF(C10>=100000,"Executive",IF(C10>=80000,"Senior",IF(C10>=60000,"Mid-Level","Junior"))) -> Mid-Level | D22: =IF(D10>=100000,"Executive",IF(D10>=80000,"Senior",IF(D10>=60000,"Mid-Level","Junior"))) -> Mid-Level | E22: =IF(E10>=100000,"Executive",IF(E10>=80000,"Senior",IF(E10>=60000,"Mid-Level","Junior"))) -> Mid-Level | F22: =IF(F10>=100000,"Executive",IF(F10>=80000,"Senior",IF(F10>=60000,"Mid-Level","Junior"))) -> Junior | G22: =IF(G10>=100000,"Executive",IF(G10>=80000,"Senior",IF(G10>=60000,"Mid-Level","Junior"))) -> Senior | H22: =IF(H10>=100000,"Executive",IF(H10>=80000,"Senior",IF(H10>=60000,"Mid-Level","Junior"))) -> Senior | I22: =IF(I10>=100000,"Executive",IF(I10>=80000,"Senior",IF(I10>=60000,"Mid-Level","Junior"))) -> Junior | ... AE22: =IF(AE10>=100000,"Executive",IF(AE10>=80000,"Senior",IF(AE10>=60000,"Mid-Level","Junior"))) -> Senior
C26: ID | D26: EMP105
C27: Employee Name | D27: =HLOOKUP(D26,A1:AF22,2,) -> Vikram Singh
C28: Gender | D28: =HLOOKUP(D26,A1:AF22,5,) -> Male
C29: Age | D29: =HLOOKUP(D26,A1:AF22,6,) -> 30

Sheet Formula Dashboard
B1: 📊 FORMULA DASHBOARD
B3: 💰 SUMIF – Total Salary by Department
B4: Total Basic Salary – IT | C4: =SUMIF('Employee Database'!E:E,"IT",'Employee Database'!M:M) -> 800000 | D4: =SUMIF('Employee Database'!E:E,"IT",'Employee Database'!M:M) -> 800000
B5: Total Basic Salary – HR | C5: =SUMIF('Employee Database'!E:E,"HR",'Employee Database'!M:M) -> 294000 | D5: =SUMIF('Employee Database'!E:E,"HR",'Employee Database'!M:M) -> 294000
B6: Total Basic Salary – Finance | C6: =SUMIF('Employee Database'!E:E,"Finance",'Employee Database'!M:M) -> 477000 | D6: =SUMIF('Employee Database'!E:E,"Finance",'Employee Database'!M:M) -> 477000
B7: Total Basic Salary – Sales | C7: =SUMIF('Employee Database'!E:E,"Sales",'Employee Database'!M:M) -> 328000 | D7: =SUMIF('Employee Database'!E:E,"Sales",'Employee Database'!M:M) -> 328000
B8: Total Basic Salary – Marketing | C8: =SUMIF('Employee Database'!E:E,"Marketing",'Employee Database'!M:M) -> 339000 | D8: =SUMIF('Employee Database'!E:E,"Marketing",'Employee Database'!M:M) -> 339000
B10: 💰 SUMIF – Total Net Salary by Department
B11: Total Net Salary – IT | C11: =SUMIF('Employee Database'!E:E,"IT",'Employee Database'!R:R) -> 1152000 | D11: =SUMIF('Employee Database'!E:E,"IT",'Employee Database'!R:R) -> 1152000
B12: Total Net Salary – HR | C12: =SUMIF('Employee Database'!E:E,"HR",'Employee Database'!R:R) -> 423360 | D12: =SUMIF('Employee Database'!E:E,"HR",'Employee Database'!R:R) -> 423360
B13: Total Net Salary – Finance | C13: =SUMIF('Employee Database'!E:E,"Finance",'Employee Database'!R:R) -> 686880 | D13: =SUMIF('Employee Database'!E:E,"Finance",'Employee Database'!R:R) -> 686880
B14: Total Net Salary – Sales | C14: =SUMIF('Employee Database'!E:E,"Sales",'Employee Database'!R:R) -> 472320 | D14: =SUMIF('Employee Database'!E:E,"Sales",'Employee Database'!R:R) -> 472320
B15: Total Net Salary – Marketing | C15: =SUMIF('Employee Database'!E:E,"Marketing",'Employee Database'!R:R) -> 488160 | D15: =SUMIF('Employee Database'!E:E,"Marketing",'Employee Database'!R:R) -> 488160
B17: 📈 AVERAGEIF – Average Salary & Rating
B18: Avg Basic Salary – IT | C18: =AVERAGEIF('Employee Database'!E:E,"IT",'Employee Database'!M:M) -> 80000 | D18: =AVERAGEIF('Employee Database'!E:E,"IT",'Employee Database'!M:M) -> 80000
B19: Avg Basic Salary – HR | C19: =AVERAGEIF('Employee Database'!E:E,"HR",'Employee Database'!M:M) -> 73500 | D19: =AVERAGEIF('Employee Database'!E:E,"HR",'Employee Database'!M:M) -> 73500
B20: Avg Basic Salary – Finance | C20: =AVERAGEIF('Employee Database'!E:E,"Finance",'Employee Database'!M:M) -> 79500 | D20: =AVERAGEIF('Employee Database'!E:E,"Finance",'Employee Database'!M:M) -> 79500
B21: Avg Basic Salary – Sales | C21: =AVERAGEIF('Employee Database'!E:E,"Sales",'Employee Database'!M:M) -> 65600 | D21: =AVERAGEIF('Employee Database'!E:E,"Sales",'Employee Database'!M:M) -> 65600
B22: Avg Basic Salary – Marketing | C22: =AVERAGEIF('Employee Database'!E:E,"Marketing",'Employee Database'!M:M) -> 67800 | D22: =AVERAGEIF('Employee Database'!E:E,"Marketing",'Employee Database'!M:M) -> 67800
B24: 📈 AVERAGEIF – Average Rating by Gender
B25: Avg Rating – Male | C25: =AVERAGEIF('Employee Database'!H:H,"Male",'Employee Database'!T:T) -> 4.2 | D25: =AVERAGEIF('Employee Database'!H:H,"Male",'Employee Database'!T:T) -> 4.2
B26: Avg Rating – Female | C26: =AVERAGEIF('Employee Database'!H:H,"Female",'Employee Database'!T:T) -> 3.6666667 | D26: =AVERAGEIF('Employee Database'!H:H,"Female",'Employee Database'!T:T) -> 3.6666667
B28: 🔢 COUNTIF – Employee Counts
B29: Total Employees – IT | C29: =COUNTIF('Employee Database'!E:E,"IT") -> 10 | D29: =COUNTIF('Employee Database'!E:E,"IT") -> 10
B30: Total Employees – HR | C30: =COUNTIF('Employee Database'!E:E,"HR") -> 4 | D30: =COUNTIF('Employee Database'!E:E,"HR") -> 4
B31: Total Employees – Finance | C31: =COUNTIF('Employee Database'!E:E,"Finance") -> 6 | D31: =COUNTIF('Employee Database'!E:E,"Finance") -> 6
B32: Total Employees – Sales | C32: =COUNTIF('Employee Database'!E:E,"Sales") -> 5 | D32: =COUNTIF('Employee Database'!E:E,"Sales") -> 5
B33: Total Employees – Marketing | C33: =COUNTIF('Employee Database'!E:E,"Marketing") -> 5 | D33: =COUNTIF('Employee Database'!E:E,"Marketing") -> 5
B34: Count of Male Employees | C34: =COUNTIF('Employee Database'!H:H,"Male") -> 15 | D34: =COUNTIF('Employee Database'!H:H,"Male") -> 15
B35: Count of Female Employees | C35: =COUNTIF('Employee Database'!H:H,"Female") -> 15 | D35: =COUNTIF('Employee Database'!H:H,"Female") -> 15
B36: Count – Excellent Performance | C36: =COUNTIF('Employee Database'!S:S,"Excellent") -> 6 | D36: =COUNTIF('Employee Database'!S:S,"Excellent") -> 6
B37: Count – Outstanding Perf. | C37: =COUNTIF('Employee Database'!S:S,"Outstanding") -> 8 | D37: =COUNTIF('Employee Database'!S:S,"Outstanding") -> 8
B38: Count – Rating = 5 | C38: =COUNTIF('Employee Database'!T:T,5) -> 10 | D38: =COUNTIF('Employee Database'!T:T,5) -> 10

Sheet VLOOKUP Tool
B1: 🔍 VLOOKUP EMPLOYEE LOOKUP TOOL
B3: ▶ Enter Employee ID (e.g. EMP101): | D3: EMP105
B5: Full Name | C5: =IFERROR(VLOOKUP($D$3,'Employee Database'!$A:$Y,2,0),"❌ Not Found") -> Vikram Singh
B6: Department | C6: =IFERROR(VLOOKUP($D$3,'Employee Database'!$A:$Y,3,0),"❌ Not Found") -> Vikram
B7: Designation | C7: =IFERROR(VLOOKUP($D$3,'Employee Database'!$A:$Y,4,0),"❌ Not Found") -> vingh
B8: Gender | C8: =IFERROR(VLOOKUP($D$3,'Employee Database'!$A:$Y,5,0),"❌ Not Found") -> Sales
B9: Age | C9: =IFERROR(VLOOKUP($D$3,'Employee Database'!$A:$Y,6,0),"❌ Not Found") -> sales executive
B10: Date of Joining | C10: =IFERROR(VLOOKUP($D$3,'Employee Database'!$A:$Y,7,0),"❌ Not Found") -> Sales Executive
B11: Experience (Yrs) | C11: =IFERROR(VLOOKUP($D$3,'Employee Database'!$A:$Y,8,0),"❌ Not Found") -> Male
B12: City | C12: =IFERROR(VLOOKUP($D$3,'Employee Database'!$A:$Y,9,0),"❌ Not Found") -> 30
B13: Basic Salary | C13: =IFERROR(VLOOKUP($D$3,'Employee Database'!$A:$Y,10,0),"❌ Not Found") -> 2020-07-05
B14: HRA | C14: =IFERROR(VLOOKUP($D$3,'Employee Database'!$A:$Y,11,0),"❌ Not Found") -> 5
B15: Allowances | C15: =IFERROR(VLOOKUP($D$3,'Employee Database'!$A:$Y,12,0),"❌ Not Found") -> Jaipur
B16: Gross Salary | C16: =IFERROR(VLOOKUP($D$3,'Employee Database'!$A:$Y,13,0),"❌ Not Found") -> 45000
B17: Tax (10%) | C17: =IFERROR(VLOOKUP($D$3,'Employee Database'!$A:$Y,14,0),"❌ Not Found") -> 18000
B18: Net Salary | C18: =IFERROR(VLOOKUP($D$3,'Employee Database'!$A:$Y,15,0),"❌ Not Found") -> 9000
B19: Performance | C19: =IFERROR(VLOOKUP($D$3,'Employee Database'!$A:$Y,16,0),"❌ Not Found") -> 72000
B20: Rating | C20: =IFERROR(VLOOKUP($D$3,'Employee Database'!$A:$Y,17,0),"❌ Not Found") -> 7200
B21: Annual Bonus | C21: =IFERROR(VLOOKUP($D$3,'Employee Database'!$A:$Y,18,0),"❌ Not Found") -> 64800
B22: Email | C22: =IFERROR(VLOOKUP($D$3,'Employee Database'!$A:$Y,19,0),"❌ Not Found") -> Average
B23: Phone | C23: =IFERROR(VLOOKUP($D$3,'Employee Database'!$A:$Y,20,0),"❌ Not Found") -> 3
B24: Salary Band | C24: =IFERROR(VLOOKUP($D$3,'Employee Database'!$A:$Y,22,0),"❌ Not Found") -> vikram.singh@company.com
B26: 💡 Tip: Change the Employee ID in cell D3 (EMP101–EMP130) to auto-populate all fields using VLOOKUP.

Sheet TEXT Formulas
B1: 📝 TEXT FORMULA EXAMPLES
B2: Formula Description | C2: Formula Syntax | D2: Result / Output
B3: UPPER – Full Name | C3: =UPPER("Aarav Sharma") -> AARAV SHARMA | D3: =UPPER("Aarav Sharma") -> AARAV SHARMA
B4: LOWER – Email | C4: =LOWER("AARAV.SHARMA@COMPANY.COM") -> aarav.sharma@company.com | D4: =LOWER("AARAV.SHARMA@COMPANY.COM") -> aarav.sharma@company.com
B5: PROPER – Department | C5: =PROPER("information technology") -> Information Technology | D5: =PROPER("information technology") -> Information Technology
B6: LEN – Name Length | C6: =LEN("Priya Patel") -> 11 | D6: =LEN("Priya Patel") -> 11
B7: LEFT – First Name | C7: =LEFT("Rohit Mehta",5) -> Rohit | D7: =LEFT("Rohit Mehta",5) -> Rohit
B8: RIGHT – Last Name (4 chars) | C8: =RIGHT("Sneha Reddy",5) -> Reddy | D8: =RIGHT("Sneha Reddy",5) -> Reddy
B9: MID – Middle chars | C9: =MID("Vikram Singh",8,5) -> Singh | D9: =MID("Vikram Singh",8,5) -> Singh
B10: FIND – Space position | C10: =FIND(" ","Kavya Nair") -> 6 | D10: =FIND(" ","Kavya Nair") -> 6
B11: TRIM – Remove extra spaces | C11: =TRIM(" Arjun Kumar ") -> Arjun Kumar | D11: =TRIM(" Arjun Kumar ") -> Arjun Kumar
B12: CONCATENATE – Full Email | C12: =_xludf.CONCAT("divya.verma@","company.com") -> #NAME? | D12: =_xludf.CONCAT("divya.verma@","company.com") -> #NAME?
B13: TEXT – Format Date | C13: =TEXT(TODAY(),"DD-MMM-YYYY") -> 28-Apr-2026 | D13: =TEXT(TODAY(),"DD-MMM-YYYY") -> 28-Apr-2026
B14: TEXT – Format Number as ₹ | C14: =TEXT(90000,"₹#,##0") -> ₹90,000 | D14: =TEXT(90000,"₹#,##0") -> ₹90,000
B15: SUBSTITUTE – Replace text | C15: =SUBSTITUTE("IT Department","IT","Tech") -> Tech Department | D15: =SUBSTITUTE("IT Department","IT","Tech") -> Tech Department
B16: REPT – Repeat char (rating) | C16: =REPT("★",4) -> ★★★★ | D16: =REPT("★",4) -> ★★★★
B17: VALUE – Text to Number | C17: =VALUE("75000") -> 75000 | D17: =VALUE("75000") -> 75000
B18: TODAY – Current Date | C18: =TODAY() -> 46140 | D18: =TODAY() -> 46140
B19: YEAR – Extract Year | C19: =YEAR(TODAY()) -> 2026 | D19: =YEAR(TODAY()) -> 2026
B20: MONTH – Extract Month | C20: =MONTH(TODAY()) -> 4 | D20: =MONTH(TODAY()) -> 4
B21: DAY – Extract Day | C21: =DAY(TODAY()) -> 28 | D21: =DAY(TODAY()) -> 28
B22: DATEDIF – Years of Exp | C22: =DATEDIF(DATE(2019,3,15),TODAY(),"Y") -> 7 | D22: =DATEDIF(DATE(2019,3,15),TODAY(),"Y") -> 7

Sheet Summary Stats
B1: 📋 SUMMARY STATISTICS
B2: – Metric
B3: OVERALL – Total Employees
B4: Total Basic Salary | C4: =SUM('Employee Database'!M3:M32) -> 2238000 | D4: =SUM('Employee Database'!M3:M32) -> 2238000
B5: Average Basic Salary | C5: =AVERAGE('Employee Database'!M3:M32) -> 74600 | D5: =AVERAGE('Employee Database'!M3:M32) -> 74600
B6: Max Basic Salary | C6: =MAX('Employee Database'!M3:M32) -> 150000 | D6: =MAX('Employee Database'!M3:M32) -> 150000
